<?xml version="1.0" encoding="utf-8"?>
<!-- This URDF was automatically created by SolidWorks to URDF Exporter! Originally created by Stephen Brawner (brawner@gmail.com) 
     Commit Version: 1.6.0-4-g7f85cfe  Build Version: 1.6.7995.38578
     For more information, please see http://wiki.ros.org/sw_urdf_exporter -->
<robot
  name="URDF">
  <!-- ✅ 新增：世界坐标系根连杆（无几何，仅作为坐标系参考） -->
  <link name="world" />

  <!-- ✅ 核心：全局旋转关节，将base_link连接到world，这里的旋转会带动整个机器人翻正 -->
  <joint name="world_to_base" type="fixed">
    <parent link="world" />
    <child link="base_link" />
    <origin xyz="0 0 0" rpy="-1.5708 0 0" />  <!-- 旋转补偿核心，优先试这个值 -->
  </joint>
  <!-- base link -->
  <link
    name="base_link">
    <inertial>
      <origin
        xyz="8.81981428078991E-05 -0.000708189608539354 0.108414515965737"
        rpy="0 0 0" />
      <mass
        value="7.86541982071816" />
      <inertia
        ixx="0.147385267820076"
        ixy="4.87232883621826E-07"
        ixz="-5.25311149906748E-06"
        iyy="0.111742631460037"
        iyz="-0.00057298476133231"
        izz="0.218839337559416" />
    </inertial>
    <visual>
      <origin
        xyz="0 0 0"
        rpy="0 0 0" />
      <geometry>
        <mesh
          filename="package://seaweashr-description/URDF/meshes/base_link.STL" />
      </geometry>
      <material
        name="">
        <color
          rgba="0.792156862745098 0.819607843137255 0.933333333333333 1" />
      </material>
    </visual>
    <collision>
      <origin
        xyz="0 0 0"
        rpy="0 0 0" />
      <geometry>
        <mesh
          filename="package://seaweashr-description/URDF/meshes/base_link.STL" />
      </geometry>
    </collision>
  </link>
  <link
    name="leftfrontwheel_Link">
    <inertial>
      <origin
        xyz="0.186 -0.26 0.07"
        rpy="0 0 0" />
      <mass
        value="0.65973" />
      <inertia
        ixx="0.001933"
        ixy="-3.9269E-19"
        ixz="-4.5173E-20"
        iyy="0.0017344"
        iyz="-3.8519E-34"
        izz="0.0017344" />
    </inertial>
    <visual>
      <origin
        xyz="0 0 0"
        rpy="0 0 0" />
      <geometry>
        <mesh
          filename="package://seaweashr-description/URDF/meshes/leftfrontwheel_Link.STL" />
      </geometry>
      <material
        name="">
        <color
          rgba="0.098039 0.098039 0.098039 1" />
      </material>
    </visual>
    <collision>
      <origin
        xyz="0 0 0"
        rpy="0 0 0" />
      <geometry>
        <mesh
          filename="package://seaweashr-description/URDF/meshes/leftfrontwheel_Link.STL" />
      </geometry>
    </collision>
  </link>
  <joint
    name="leftfrontjoint"
    type="continuous">
    <origin
      xyz="0 -0.34223 -0.083776"
      rpy="-3.1416 0 0" />
    <parent
      link="base_link" />
    <child
      link="leftfrontwheel_Link" />
    <axis
      xyz="1 0 0" />
  </joint>
  <link
    name="rightfrontwheel_Link">
    <inertial>
      <origin
        xyz="-0.186 -0.26 0.07"
        rpy="0 0 0" />
      <mass
        value="0.659734457253857" />
      <inertia
        ixx="0.0019330219597538"
        ixy="-9.92924677451742E-20"
        ixz="-2.06720667964179E-21"
        iyy="0.00173444188812039"
        iyz="-1.6940658945086E-21"
        izz="0.00173444188812039" />
    </inertial>
    <visual>
      <origin
        xyz="0 0 0"
        rpy="0 0 0" />
      <geometry>
        <mesh
          filename="package://seaweashr-description/URDF/meshes/rightfrontwheel_Link.STL" />
      </geometry>
      <material
        name="">
        <color
          rgba="0.0980392156862745 0.0980392156862745 0.0980392156862745 1" />
      </material>
    </visual>
    <collision>
      <origin
        xyz="0 0 0"
        rpy="0 0 0" />
      <geometry>
        <mesh
          filename="package://seaweashr-description/URDF/meshes/rightfrontwheel_Link.STL" />
      </geometry>
    </collision>
  </link>
  <joint
    name="rightfrontjoint"
    type="continuous">
    <origin
      xyz="0 -0.013227 0.10649"
      rpy="1.5746 0 0" />
    <parent
      link="base_link" />
    <child
      link="rightfrontwheel_Link" />
    <axis
      xyz="1 0 0" />
  </joint>
  <link
    name="leftbackwheel_Link">
    <inertial>
      <origin
        xyz="0.186 0.04 0.07"
        rpy="0 0 0" />
      <mass
        value="0.659734457253857" />
      <inertia
        ixx="0.0019330219597538"
        ixy="-8.9053195220116E-19"
        ixz="-4.51725970653216E-20"
        iyy="0.00173444188812039"
        iyz="4.22185817084977E-35"
        izz="0.00173444188812039" />
    </inertial>
    <visual>
      <origin
        xyz="0 0 0"
        rpy="0 0 0" />
      <geometry>
        <mesh
          filename="package://seaweashr-description/URDF/meshes/leftbackwheel_Link.STL" />
      </geometry>
      <material
        name="">
        <color
          rgba="0.0980392156862745 0.0980392156862745 0.0980392156862745 1" />
      </material>
    </visual>
    <collision>
      <origin
        xyz="0 0 0"
        rpy="0 0 0" />
      <geometry>
        <mesh
          filename="package://seaweashr-description/URDF/meshes/leftbackwheel_Link.STL" />
      </geometry>
    </collision>
  </link>
  <joint
    name="leftbackjoint"
    type="continuous">
    <origin
      xyz="0 -0.012228 0.11249"
      rpy="1.5708 0 0" />
    <parent
      link="base_link" />
    <child
      link="leftbackwheel_Link" />
    <axis
      xyz="1 0 0" />
  </joint>
  <link
    name="rightbackwheel_Link">
    <inertial>
      <origin
        xyz="-0.186 0.04 0.07"
        rpy="0 0 0" />
      <mass
        value="0.659734457253857" />
      <inertia
        ixx="0.0019330219597538"
        ixy="8.89049644543465E-19"
        ixz="1.88079096131566E-34"
        iyy="0.00173444188812039"
        iyz="1.81464585269469E-36"
        izz="0.00173444188812039" />
    </inertial>
    <visual>
      <origin
        xyz="0 0 0"
        rpy="0 0 0" />
      <geometry>
        <mesh
          filename="package://seaweashr-description/URDF/meshes/rightbackwheel_Link.STL" />
      </geometry>
      <material
        name="">
        <color
          rgba="0.0980392156862745 0.0980392156862745 0.0980392156862745 1" />
      </material>
    </visual>
    <collision>
      <origin
        xyz="0 0 0"
        rpy="0 0 0" />
      <geometry>
        <mesh
          filename="package://seaweashr-description/URDF/meshes/rightbackwheel_Link.STL" />
      </geometry>
    </collision>
  </link>
  <joint
    name="rightbackjoint"
    type="continuous">
    <origin
      xyz="0 -0.012228 0.11249"
      rpy="1.5708 0 0" />
    <parent
      link="base_link" />
    <child
      link="rightbackwheel_Link" />
    <axis
      xyz="1 0 0" />
  </joint>
  <link
    name="leftmotor_Link">
    <inertial>
      <origin
        xyz="0.0950000014156103 -0.0200000002980232 0.16"
        rpy="0 0 0" />
      <mass
        value="0.00785397718670416" />
      <inertia
        ixx="6.59406831854161E-06"
        ixy="5.9740946667467E-56"
        ixz="6.91076009765075E-40"
        iyy="6.59406831854161E-06"
        iyz="-3.79438902730694E-39"
        izz="9.81746592429545E-08" />
    </inertial>
    <visual>
      <origin
        xyz="0 0 0"
        rpy="0 0 0" />
      <geometry>
        <mesh
          filename="package://seaweashr-description/URDF/meshes/leftmotor_Link.STL" />
      </geometry>
      <material
        name="">
        <color
          rgba="0.627450980392157 0.627450980392157 0.627450980392157 1" />
      </material>
    </visual>
    <collision>
      <origin
        xyz="0 0 0"
        rpy="0 0 0" />
      <geometry>
        <mesh
          filename="package://seaweashr-description/URDF/meshes/leftmotor_Link.STL" />
      </geometry>
    </collision>
  </link>
  <joint
    name="leftmotorjoint"
    type="continuous">
    <origin
      xyz="0 -0.32 -0.04"
      rpy="-1.5708 0 0" />
    <parent
      link="base_link" />
    <child
      link="leftmotor_Link" />
    <axis
      xyz="0 0 1" />
  </joint>
  <link
    name="rightmotor_Link">
    <inertial>
      <origin
        xyz="-0.095093 -0.019554 0.16"
        rpy="0 0 0" />
      <mass
        value="0.007854" />
      <inertia
        ixx="6.5941E-06"
        ixy="0"
        ixz="8.0933E-28"
        iyy="6.5941E-06"
        iyz="1.7233E-25"
        izz="9.8175E-08" />
    </inertial>
    <visual>
      <origin
        xyz="0 0 0"
        rpy="0 0 0" />
      <geometry>
        <mesh
          filename="file:///home/tse-yatsing/Underwater_Cleaning_Robot/Software/SeaWashr-ros2-ws/src/seaweashr-description/URDF/meshes/rightmotor_Link.STL" />
      </geometry>
      <material
        name="">
        <color
          rgba="0.62745 0.62745 0.62745 1" />
      </material>
    </visual>
    <collision>
      <origin
        xyz="0 0 0"
        rpy="0 0 0" />
      <geometry>
        <mesh
          filename="package://seaweashr-description/URDF/meshes/rightmotor_Link.STL" />
      </geometry>
    </collision>
  </link>
  <joint
    name="rightmotorjoint"
    type="continuous">
    <origin
      xyz="0 -0.32 -0.04"
      rpy="-1.5708 0.0046964 0" />
    <parent
      link="base_link" />
    <child
      link="rightmotor_Link" />
    <axis
      xyz="0 0 1" />
  </joint>
</robot>